 * Running on http://127.0.0.1:8943/ (Press CTRL+C to quit)
127.0.0.1 - - [18/Oct/2016 23:41:42] "GET / HTTP/1.1" 200 -
127.0.0.1 - - [18/Oct/2016 23:41:42] "GET /favicon.ico HTTP/1.1" 404 -
127.0.0.1 - - [18/Oct/2016 23:41:42] "GET /favicon.ico HTTP/1.1" 404 -
127.0.0.1 - - [18/Oct/2016 23:41:42] "POST / HTTP/1.1" 200 -
127.0.0.1 - - [18/Oct/2016 23:41:43] "POST / HTTP/1.1" 500 -
Traceback (most recent call last):
  File "/usr/local/lib/python3.5/site-packages/flask/app.py", line 1836, in __call__
    return self.wsgi_app(environ, start_response)
  File "/usr/local/lib/python3.5/site-packages/flask/app.py", line 1820, in wsgi_app
    response = self.make_response(self.handle_exception(e))
  File "/usr/local/lib/python3.5/site-packages/flask/app.py", line 1403, in handle_exception
    reraise(exc_type, exc_value, tb)
  File "/usr/local/lib/python3.5/site-packages/flask/_compat.py", line 33, in reraise
    raise value
  File "/usr/local/lib/python3.5/site-packages/flask/app.py", line 1817, in wsgi_app
    response = self.full_dispatch_request()
  File "/usr/local/lib/python3.5/site-packages/flask/app.py", line 1477, in full_dispatch_request
    rv = self.handle_user_exception(e)
  File "/usr/local/lib/python3.5/site-packages/flask/app.py", line 1381, in handle_user_exception
    reraise(exc_type, exc_value, tb)
  File "/usr/local/lib/python3.5/site-packages/flask/_compat.py", line 33, in reraise
    raise value
  File "/usr/local/lib/python3.5/site-packages/flask/app.py", line 1475, in full_dispatch_request
    rv = self.dispatch_request()
  File "/usr/local/lib/python3.5/site-packages/flask/app.py", line 1461, in dispatch_request
    return self.view_functions[rule.endpoint](**req.view_args)
  File "/usr/src/app/stockdata/views.py", line 15, in index
    stock = stockdata[request.form['symbol']]
KeyError: 'INVALID'
127.0.0.1 - - [18/Oct/2016 23:41:43] "GET /?__debugger__=yes&cmd=resource&f=style.css HTTP/1.1" 200 -
127.0.0.1 - - [18/Oct/2016 23:41:43] "GET /?__debugger__=yes&cmd=resource&f=jquery.js HTTP/1.1" 200 -
127.0.0.1 - - [18/Oct/2016 23:41:43] "GET /?__debugger__=yes&cmd=resource&f=debugger.js HTTP/1.1" 200 -
127.0.0.1 - - [18/Oct/2016 23:41:43] "GET /?__debugger__=yes&cmd=resource&f=console.png HTTP/1.1" 200 -
127.0.0.1 - - [18/Oct/2016 23:41:43] "GET /?__debugger__=yes&cmd=resource&f=ubuntu.ttf HTTP/1.1" 200 -
127.0.0.1 - - [18/Oct/2016 23:41:43] "GET /?__debugger__=yes&cmd=resource&f=console.png HTTP/1.1" 200 -
127.0.0.1 - - [18/Oct/2016 23:41:43] "GET /?__debugger__=yes&cmd=resource&f=source.png HTTP/1.1" 200 -
F.ETraceback (most recent call last):
  File "acceptance_tests/acceptance_tests.py", line 90, in <module>
    unittest.main()
  File "/usr/local/lib/python3.5/unittest/main.py", line 94, in __init__
    self.runTests()
  File "/usr/local/lib/python3.5/unittest/main.py", line 255, in runTests
    self.result = testRunner.run(self.test)
  File "/usr/local/lib/python3.5/unittest/runner.py", line 176, in run
    test(result)
  File "/usr/local/lib/python3.5/unittest/suite.py", line 84, in __call__
    return self.run(*args, **kwds)
  File "/usr/local/lib/python3.5/unittest/suite.py", line 122, in run
    test(result)
  File "/usr/local/lib/python3.5/unittest/suite.py", line 84, in __call__
    return self.run(*args, **kwds)
  File "/usr/local/lib/python3.5/unittest/suite.py", line 122, in run
    test(result)
  File "/usr/local/lib/python3.5/site-packages/flask_testing/utils.py", line 112, in __call__
    self._post_teardown()
  File "/usr/local/lib/python3.5/site-packages/flask_testing/utils.py", line 149, in _post_teardown
    self._ctx.pop()
  File "/usr/local/lib/python3.5/site-packages/flask/ctx.py", line 357, in pop
    % (rv, self)
AssertionError: Popped wrong request context.  (<RequestContext 'http://localhost/' [POST] of stockdata> instead of <RequestContext 'http://localhost/' [GET] of stockdata>)
